[2025-03-22 14:56:23,521] INFO _log() L97    * Restarting with stat - call_trace=d:\Desenvolvimento\PUC\rescue-api\.venv\Lib\site-packages\werkzeug\_internal.py L97  
[2025-03-22 14:56:26,446] INFO _log() L97    * Detected change in 'D:\\Desenvolvimento\\PUC\\rescue-api\\app.py', reloading - call_trace=d:\Desenvolvimento\PUC\rescue-api\.venv\Lib\site-packages\werkzeug\_internal.py L97  
[2025-03-22 14:56:26,650] INFO _log() L97    * Restarting with stat - call_trace=d:\Desenvolvimento\PUC\rescue-api\.venv\Lib\site-packages\werkzeug\_internal.py L97  
[2025-03-22 14:56:31,682] INFO _log() L97    * Detected change in 'D:\\Desenvolvimento\\PUC\\rescue-api\\app.py', reloading - call_trace=d:\Desenvolvimento\PUC\rescue-api\.venv\Lib\site-packages\werkzeug\_internal.py L97  
[2025-03-22 14:56:31,835] INFO _log() L97    * Restarting with stat - call_trace=d:\Desenvolvimento\PUC\rescue-api\.venv\Lib\site-packages\werkzeug\_internal.py L97  
[2025-03-22 14:56:36,600] INFO _log() L97    * Detected change in 'D:\\Desenvolvimento\\PUC\\rescue-api\\app.py', reloading - call_trace=d:\Desenvolvimento\PUC\rescue-api\.venv\Lib\site-packages\werkzeug\_internal.py L97  
[2025-03-22 14:56:36,799] INFO _log() L97    * Restarting with stat - call_trace=d:\Desenvolvimento\PUC\rescue-api\.venv\Lib\site-packages\werkzeug\_internal.py L97  
[2025-03-22 14:56:41,669] INFO _log() L97    * Detected change in 'D:\\Desenvolvimento\\PUC\\rescue-api\\app.py', reloading - call_trace=d:\Desenvolvimento\PUC\rescue-api\.venv\Lib\site-packages\werkzeug\_internal.py L97  
[2025-03-22 14:56:41,823] INFO _log() L97    * Restarting with stat - call_trace=d:\Desenvolvimento\PUC\rescue-api\.venv\Lib\site-packages\werkzeug\_internal.py L97  
[2025-03-22 14:56:45,702] INFO _log() L97    * Detected change in 'D:\\Desenvolvimento\\PUC\\rescue-api\\app.py', reloading - call_trace=d:\Desenvolvimento\PUC\rescue-api\.venv\Lib\site-packages\werkzeug\_internal.py L97  
[2025-03-22 14:56:45,865] INFO _log() L97    * Restarting with stat - call_trace=d:\Desenvolvimento\PUC\rescue-api\.venv\Lib\site-packages\werkzeug\_internal.py L97  
[2025-03-22 14:56:57,132] INFO _log() L97    * Detected change in 'D:\\Desenvolvimento\\PUC\\rescue-api\\app.py', reloading - call_trace=d:\Desenvolvimento\PUC\rescue-api\.venv\Lib\site-packages\werkzeug\_internal.py L97  
[2025-03-22 14:56:57,286] INFO _log() L97    * Restarting with stat - call_trace=d:\Desenvolvimento\PUC\rescue-api\.venv\Lib\site-packages\werkzeug\_internal.py L97  
[2025-03-22 14:57:07,384] INFO _log() L97    * Detected change in 'D:\\Desenvolvimento\\PUC\\rescue-api\\app.py', reloading - call_trace=d:\Desenvolvimento\PUC\rescue-api\.venv\Lib\site-packages\werkzeug\_internal.py L97  
[2025-03-22 14:57:07,530] INFO _log() L97    * Restarting with stat - call_trace=d:\Desenvolvimento\PUC\rescue-api\.venv\Lib\site-packages\werkzeug\_internal.py L97  
[2025-03-22 14:57:12,368] INFO _log() L97    * Detected change in 'D:\\Desenvolvimento\\PUC\\rescue-api\\app.py', reloading - call_trace=d:\Desenvolvimento\PUC\rescue-api\.venv\Lib\site-packages\werkzeug\_internal.py L97  
[2025-03-22 14:57:12,567] INFO _log() L97    * Restarting with stat - call_trace=d:\Desenvolvimento\PUC\rescue-api\.venv\Lib\site-packages\werkzeug\_internal.py L97  
[2025-03-22 14:57:17,368] INFO _log() L97    * Detected change in 'D:\\Desenvolvimento\\PUC\\rescue-api\\app.py', reloading - call_trace=d:\Desenvolvimento\PUC\rescue-api\.venv\Lib\site-packages\werkzeug\_internal.py L97  
[2025-03-22 14:57:17,516] INFO _log() L97    * Restarting with stat - call_trace=d:\Desenvolvimento\PUC\rescue-api\.venv\Lib\site-packages\werkzeug\_internal.py L97  
[2025-03-22 14:57:29,871] INFO _log() L97    * Detected change in 'D:\\Desenvolvimento\\PUC\\rescue-api\\app.py', reloading - call_trace=d:\Desenvolvimento\PUC\rescue-api\.venv\Lib\site-packages\werkzeug\_internal.py L97  
[2025-03-22 14:57:30,051] INFO _log() L97    * Restarting with stat - call_trace=d:\Desenvolvimento\PUC\rescue-api\.venv\Lib\site-packages\werkzeug\_internal.py L97  
[2025-03-22 14:57:32,866] INFO _log() L97   127.0.0.1 - - [22/Mar/2025 14:57:32] "[35m[1mGET /openapi/swagger HTTP/1.1[0m" 500 - - call_trace=d:\Desenvolvimento\PUC\rescue-api\.venv\Lib\site-packages\werkzeug\_internal.py L97  
[2025-03-22 14:57:32,912] ERROR _log() L97   Error on request:
Traceback (most recent call last):
  File "d:\Desenvolvimento\PUC\rescue-api\.venv\Lib\site-packages\werkzeug\serving.py", line 370, in run_wsgi
    execute(self.server.app)
    ~~~~~~~^^^^^^^^^^^^^^^^^
  File "d:\Desenvolvimento\PUC\rescue-api\.venv\Lib\site-packages\werkzeug\serving.py", line 331, in execute
    application_iter = app(environ, start_response)
  File "d:\Desenvolvimento\PUC\rescue-api\.venv\Lib\site-packages\flask\cli.py", line 972, in app
    raise err from None
  File "d:\Desenvolvimento\PUC\rescue-api\.venv\Lib\site-packages\flask\cli.py", line 961, in run_command
    app: WSGIApplication = info.load_app()  # pyright: ignore
                           ~~~~~~~~~~~~~^^
  File "d:\Desenvolvimento\PUC\rescue-api\.venv\Lib\site-packages\flask\cli.py", line 353, in load_app
    app = locate_app(import_name, None, raise_if_not_found=False)
  File "d:\Desenvolvimento\PUC\rescue-api\.venv\Lib\site-packages\flask\cli.py", line 245, in locate_app
    __import__(module_name)
    ~~~~~~~~~~^^^^^^^^^^^^^
  File "D:\Desenvolvimento\PUC\rescue-api\app.py", line 169, in <module>
    @app.delete('/rescue-point', tags=[rescue_point_tag],
     ^^^^^^^^^^^^^^^^^^^^^^^^^^^^^^^^^^^^^^^^^^^^^^^^^^^^
  File "d:\Desenvolvimento\PUC\rescue-api\.venv\Lib\site-packages\flask_openapi3\scaffold.py", line 371, in decorator
    self._add_url_rule(rule, view_func=view_func, **options)
    ~~~~~~~~~~~~~~~~~~^^^^^^^^^^^^^^^^^^^^^^^^^^^^^^^^^^^^^^
  File "d:\Desenvolvimento\PUC\rescue-api\.venv\Lib\site-packages\flask_openapi3\openapi.py", line 366, in _add_url_rule
    self.add_url_rule(rule, endpoint, view_func, provide_automatic_options, **options)
    ~~~~~~~~~~~~~~~~~^^^^^^^^^^^^^^^^^^^^^^^^^^^^^^^^^^^^^^^^^^^^^^^^^^^^^^^^^^^^^^^^^
  File "d:\Desenvolvimento\PUC\rescue-api\.venv\Lib\site-packages\flask\sansio\scaffold.py", line 47, in wrapper_func
    return f(self, *args, **kwargs)
  File "d:\Desenvolvimento\PUC\rescue-api\.venv\Lib\site-packages\flask\sansio\app.py", line 657, in add_url_rule
    raise AssertionError(
    ^
AssertionError: View function mapping is overwriting an existing endpoint function: del_produto - call_trace=d:\Desenvolvimento\PUC\rescue-api\.venv\Lib\site-packages\werkzeug\_internal.py L97  
[2025-03-22 14:57:33,061] INFO _log() L97   127.0.0.1 - - [22/Mar/2025 14:57:33] "[35m[1mGET /favicon.ico HTTP/1.1[0m" 500 - - call_trace=d:\Desenvolvimento\PUC\rescue-api\.venv\Lib\site-packages\werkzeug\_internal.py L97  
[2025-03-22 14:57:33,074] ERROR _log() L97   Error on request:
Traceback (most recent call last):
  File "d:\Desenvolvimento\PUC\rescue-api\.venv\Lib\site-packages\werkzeug\serving.py", line 370, in run_wsgi
    execute(self.server.app)
    ~~~~~~~^^^^^^^^^^^^^^^^^
  File "d:\Desenvolvimento\PUC\rescue-api\.venv\Lib\site-packages\werkzeug\serving.py", line 331, in execute
    application_iter = app(environ, start_response)
  File "d:\Desenvolvimento\PUC\rescue-api\.venv\Lib\site-packages\flask\cli.py", line 972, in app
    raise err from None
  File "d:\Desenvolvimento\PUC\rescue-api\.venv\Lib\site-packages\werkzeug\serving.py", line 370, in run_wsgi
    execute(self.server.app)
    ~~~~~~~^^^^^^^^^^^^^^^^^
  File "d:\Desenvolvimento\PUC\rescue-api\.venv\Lib\site-packages\werkzeug\serving.py", line 331, in execute
    application_iter = app(environ, start_response)
  File "d:\Desenvolvimento\PUC\rescue-api\.venv\Lib\site-packages\flask\cli.py", line 972, in app
    raise err from None
  File "d:\Desenvolvimento\PUC\rescue-api\.venv\Lib\site-packages\flask\cli.py", line 961, in run_command
    app: WSGIApplication = info.load_app()  # pyright: ignore
                           ~~~~~~~~~~~~~^^
  File "d:\Desenvolvimento\PUC\rescue-api\.venv\Lib\site-packages\flask\cli.py", line 353, in load_app
    app = locate_app(import_name, None, raise_if_not_found=False)
  File "d:\Desenvolvimento\PUC\rescue-api\.venv\Lib\site-packages\flask\cli.py", line 245, in locate_app
    __import__(module_name)
    ~~~~~~~~~~^^^^^^^^^^^^^
  File "D:\Desenvolvimento\PUC\rescue-api\app.py", line 169, in <module>
    @app.delete('/rescue-point', tags=[rescue_point_tag],
     ^^^^^^^^^^^^^^^^^^^^^^^^^^^^^^^^^^^^^^^^^^^^^^^^^^^^
  File "d:\Desenvolvimento\PUC\rescue-api\.venv\Lib\site-packages\flask_openapi3\scaffold.py", line 371, in decorator
    self._add_url_rule(rule, view_func=view_func, **options)
    ~~~~~~~~~~~~~~~~~~^^^^^^^^^^^^^^^^^^^^^^^^^^^^^^^^^^^^^^
  File "d:\Desenvolvimento\PUC\rescue-api\.venv\Lib\site-packages\flask_openapi3\openapi.py", line 366, in _add_url_rule
    self.add_url_rule(rule, endpoint, view_func, provide_automatic_options, **options)
    ~~~~~~~~~~~~~~~~~^^^^^^^^^^^^^^^^^^^^^^^^^^^^^^^^^^^^^^^^^^^^^^^^^^^^^^^^^^^^^^^^^
  File "d:\Desenvolvimento\PUC\rescue-api\.venv\Lib\site-packages\flask\sansio\scaffold.py", line 47, in wrapper_func
    return f(self, *args, **kwargs)
  File "d:\Desenvolvimento\PUC\rescue-api\.venv\Lib\site-packages\flask\sansio\app.py", line 657, in add_url_rule
    raise AssertionError(
    ^
AssertionError: View function mapping is overwriting an existing endpoint function: del_produto - call_trace=d:\Desenvolvimento\PUC\rescue-api\.venv\Lib\site-packages\werkzeug\_internal.py L97  
[2025-03-22 14:58:41,800] INFO _log() L97   [31m[1mWARNING: This is a development server. Do not use it in a production deployment. Use a production WSGI server instead.[0m
 * Running on http://127.0.0.1:5000 - call_trace=d:\Desenvolvimento\PUC\rescue-api\.venv\Lib\site-packages\werkzeug\_internal.py L97  
