[2025-04-10 20:00:07,805] INFO _log() L97   [31m[1mWARNING: This is a development server. Do not use it in a production deployment. Use a production WSGI server instead.[0m
 * Running on http://127.0.0.1:5000 - call_trace=d:\Desenvolvimento\PUC\rescue-api\.venv\Lib\site-packages\werkzeug\_internal.py L97  
[2025-04-10 20:00:07,843] INFO _log() L97   [33mPress CTRL+C to quit[0m - call_trace=d:\Desenvolvimento\PUC\rescue-api\.venv\Lib\site-packages\werkzeug\_internal.py L97  
[2025-04-10 20:00:07,884] INFO _log() L97    * Restarting with stat - call_trace=d:\Desenvolvimento\PUC\rescue-api\.venv\Lib\site-packages\werkzeug\_internal.py L97  
[2025-04-10 20:01:15,359] INFO _log() L97   127.0.0.1 - - [10/Apr/2025 20:01:15] "GET /rescue-point HTTP/1.1" 200 - - call_trace=d:\Desenvolvimento\PUC\rescue-api\.venv\Lib\site-packages\werkzeug\_internal.py L97  
[2025-04-10 20:01:46,318] INFO _log() L97   127.0.0.1 - - [10/Apr/2025 20:01:46] "GET /rescue-point HTTP/1.1" 200 - - call_trace=d:\Desenvolvimento\PUC\rescue-api\.venv\Lib\site-packages\werkzeug\_internal.py L97  
[2025-04-10 20:01:51,163] INFO _log() L97   127.0.0.1 - - [10/Apr/2025 20:01:51] "GET /rescue-point HTTP/1.1" 200 - - call_trace=d:\Desenvolvimento\PUC\rescue-api\.venv\Lib\site-packages\werkzeug\_internal.py L97  
[2025-04-10 20:01:57,618] INFO _log() L97   127.0.0.1 - - [10/Apr/2025 20:01:57] "GET /rescue-point HTTP/1.1" 200 - - call_trace=d:\Desenvolvimento\PUC\rescue-api\.venv\Lib\site-packages\werkzeug\_internal.py L97  
[2025-04-10 20:02:17,679] INFO _log() L97   127.0.0.1 - - [10/Apr/2025 20:02:17] "GET /rescue-point HTTP/1.1" 200 - - call_trace=d:\Desenvolvimento\PUC\rescue-api\.venv\Lib\site-packages\werkzeug\_internal.py L97  
[2025-04-10 20:02:24,237] INFO _log() L97   127.0.0.1 - - [10/Apr/2025 20:02:24] "GET /rescue-point HTTP/1.1" 200 - - call_trace=d:\Desenvolvimento\PUC\rescue-api\.venv\Lib\site-packages\werkzeug\_internal.py L97  
[2025-04-10 20:02:32,423] INFO _log() L97   127.0.0.1 - - [10/Apr/2025 20:02:32] "GET /vehicule HTTP/1.1" 200 - - call_trace=d:\Desenvolvimento\PUC\rescue-api\.venv\Lib\site-packages\werkzeug\_internal.py L97  
[2025-04-10 20:02:33,969] INFO _log() L97   127.0.0.1 - - [10/Apr/2025 20:02:33] "GET /rescue-point HTTP/1.1" 200 - - call_trace=d:\Desenvolvimento\PUC\rescue-api\.venv\Lib\site-packages\werkzeug\_internal.py L97  
[2025-04-10 20:15:05,732] INFO _log() L97   127.0.0.1 - - [10/Apr/2025 20:15:05] "GET /rescue-point HTTP/1.1" 200 - - call_trace=d:\Desenvolvimento\PUC\rescue-api\.venv\Lib\site-packages\werkzeug\_internal.py L97  
[2025-04-10 20:15:22,123] INFO _log() L97   127.0.0.1 - - [10/Apr/2025 20:15:22] "GET /rescue-point HTTP/1.1" 200 - - call_trace=d:\Desenvolvimento\PUC\rescue-api\.venv\Lib\site-packages\werkzeug\_internal.py L97  
[2025-04-10 20:15:23,376] INFO _log() L97   127.0.0.1 - - [10/Apr/2025 20:15:23] "GET /rescue-point HTTP/1.1" 200 - - call_trace=d:\Desenvolvimento\PUC\rescue-api\.venv\Lib\site-packages\werkzeug\_internal.py L97  
[2025-04-10 20:15:56,847] INFO _log() L97   127.0.0.1 - - [10/Apr/2025 20:15:56] "GET /rescue-point HTTP/1.1" 200 - - call_trace=d:\Desenvolvimento\PUC\rescue-api\.venv\Lib\site-packages\werkzeug\_internal.py L97  
[2025-04-10 20:15:57,916] INFO _log() L97   127.0.0.1 - - [10/Apr/2025 20:15:57] "GET /rescue-point HTTP/1.1" 200 - - call_trace=d:\Desenvolvimento\PUC\rescue-api\.venv\Lib\site-packages\werkzeug\_internal.py L97  
[2025-04-10 20:18:00,747] INFO _log() L97   127.0.0.1 - - [10/Apr/2025 20:18:00] "GET /rescue-point HTTP/1.1" 200 - - call_trace=d:\Desenvolvimento\PUC\rescue-api\.venv\Lib\site-packages\werkzeug\_internal.py L97  
[2025-04-10 20:18:13,651] INFO _log() L97   127.0.0.1 - - [10/Apr/2025 20:18:13] "GET /rescue-point HTTP/1.1" 200 - - call_trace=d:\Desenvolvimento\PUC\rescue-api\.venv\Lib\site-packages\werkzeug\_internal.py L97  
[2025-04-10 20:19:01,868] ERROR log_exception() L875  Exception on /rescue-point [GET] - call_trace=d:\Desenvolvimento\PUC\rescue-api\.venv\Lib\site-packages\flask\app.py L875 
Traceback (most recent call last):
  File "d:\Desenvolvimento\PUC\rescue-api\.venv\Lib\site-packages\flask\app.py", line 1511, in wsgi_app
    response = self.full_dispatch_request()
  File "d:\Desenvolvimento\PUC\rescue-api\.venv\Lib\site-packages\flask\app.py", line 919, in full_dispatch_request
    rv = self.handle_user_exception(e)
  File "d:\Desenvolvimento\PUC\rescue-api\.venv\Lib\site-packages\flask_cors\extension.py", line 176, in wrapped_function
    return cors_after_request(app.make_response(f(*args, **kwargs)))
                                                ~^^^^^^^^^^^^^^^^^
  File "d:\Desenvolvimento\PUC\rescue-api\.venv\Lib\site-packages\flask\app.py", line 917, in full_dispatch_request
    rv = self.dispatch_request()
  File "d:\Desenvolvimento\PUC\rescue-api\.venv\Lib\site-packages\flask\app.py", line 902, in dispatch_request
    return self.ensure_sync(self.view_functions[rule.endpoint])(**view_args)  # type: ignore[no-any-return]
           ~~~~~~~~~~~~~~~~~~~~~~~~~~~~~~~~~~~~~~~~~~~~~~~~~~~~^^^^^^^^^^^^^
  File "d:\Desenvolvimento\PUC\rescue-api\.venv\Lib\site-packages\flask_openapi3\scaffold.py", line 117, in view_func
    response = func(**func_kwargs)
  File "D:\Desenvolvimento\PUC\rescue-api\app.py", line 162, in get_all_rescue_points
    rescue_points = session.query(RescuePoint).filter(RescuePoint.status == True).all()
  File "d:\Desenvolvimento\PUC\rescue-api\.venv\Lib\site-packages\sqlalchemy\orm\query.py", line 2704, in all
    return self._iter().all()  # type: ignore
           ~~~~~~~~~~^^
  File "d:\Desenvolvimento\PUC\rescue-api\.venv\Lib\site-packages\sqlalchemy\orm\query.py", line 2858, in _iter
    result: Union[ScalarResult[_T], Result[_T]] = self.session.execute(
                                                  ~~~~~~~~~~~~~~~~~~~~^
        statement,
        ^^^^^^^^^^
        params,
        ^^^^^^^
        execution_options={"_sa_orm_load_options": self.load_options},
        ^^^^^^^^^^^^^^^^^^^^^^^^^^^^^^^^^^^^^^^^^^^^^^^^^^^^^^^^^^^^^^
    )
    ^
  File "d:\Desenvolvimento\PUC\rescue-api\.venv\Lib\site-packages\sqlalchemy\orm\session.py", line 2365, in execute
    return self._execute_internal(
           ~~~~~~~~~~~~~~~~~~~~~~^
        statement,
        ^^^^^^^^^^
    ...<4 lines>...
        _add_event=_add_event,
        ^^^^^^^^^^^^^^^^^^^^^^
    )
    ^
  File "d:\Desenvolvimento\PUC\rescue-api\.venv\Lib\site-packages\sqlalchemy\orm\session.py", line 2241, in _execute_internal
    conn = self._connection_for_bind(bind)
  File "d:\Desenvolvimento\PUC\rescue-api\.venv\Lib\site-packages\sqlalchemy\orm\session.py", line 2110, in _connection_for_bind
    return trans._connection_for_bind(engine, execution_options)
           ~~~~~~~~~~~~~~~~~~~~~~~~~~^^^^^^^^^^^^^^^^^^^^^^^^^^^
  File "<string>", line 2, in _connection_for_bind
  File "d:\Desenvolvimento\PUC\rescue-api\.venv\Lib\site-packages\sqlalchemy\orm\state_changes.py", line 139, in _go
    ret_value = fn(self, *arg, **kw)
  File "d:\Desenvolvimento\PUC\rescue-api\.venv\Lib\site-packages\sqlalchemy\orm\session.py", line 1189, in _connection_for_bind
    conn = bind.connect()
  File "d:\Desenvolvimento\PUC\rescue-api\.venv\Lib\site-packages\sqlalchemy\engine\base.py", line 3274, in connect
    return self._connection_cls(self)
           ~~~~~~~~~~~~~~~~~~~~^^^^^^
  File "d:\Desenvolvimento\PUC\rescue-api\.venv\Lib\site-packages\sqlalchemy\engine\base.py", line 146, in __init__
    self._dbapi_connection = engine.raw_connection()
                             ~~~~~~~~~~~~~~~~~~~~~^^
  File "d:\Desenvolvimento\PUC\rescue-api\.venv\Lib\site-packages\sqlalchemy\engine\base.py", line 3298, in raw_connection
    return self.pool.connect()
           ~~~~~~~~~~~~~~~~~^^
  File "d:\Desenvolvimento\PUC\rescue-api\.venv\Lib\site-packages\sqlalchemy\pool\base.py", line 449, in connect
    return _ConnectionFairy._checkout(self)
           ~~~~~~~~~~~~~~~~~~~~~~~~~~^^^^^^
  File "d:\Desenvolvimento\PUC\rescue-api\.venv\Lib\site-packages\sqlalchemy\pool\base.py", line 1264, in _checkout
    fairy = _ConnectionRecord.checkout(pool)
  File "d:\Desenvolvimento\PUC\rescue-api\.venv\Lib\site-packages\sqlalchemy\pool\base.py", line 713, in checkout
    rec = pool._do_get()
  File "d:\Desenvolvimento\PUC\rescue-api\.venv\Lib\site-packages\sqlalchemy\pool\impl.py", line 168, in _do_get
    raise exc.TimeoutError(
    ...<4 lines>...
    )
sqlalchemy.exc.TimeoutError: QueuePool limit of size 5 overflow 10 reached, connection timed out, timeout 30.00 (Background on this error at: https://sqlalche.me/e/20/3o7r)
[2025-04-10 20:19:02,352] INFO _log() L97   127.0.0.1 - - [10/Apr/2025 20:19:02] "[35m[1mGET /rescue-point HTTP/1.1[0m" 500 - - call_trace=d:\Desenvolvimento\PUC\rescue-api\.venv\Lib\site-packages\werkzeug\_internal.py L97  
[2025-04-10 20:24:59,670] INFO _log() L97   127.0.0.1 - - [10/Apr/2025 20:24:59] "[35m[1mGET /rescue-point HTTP/1.1[0m" 500 - - call_trace=d:\Desenvolvimento\PUC\rescue-api\.venv\Lib\site-packages\werkzeug\_internal.py L97  
[2025-04-10 20:25:14,815] INFO _log() L97   [31m[1mWARNING: This is a development server. Do not use it in a production deployment. Use a production WSGI server instead.[0m
 * Running on http://127.0.0.1:5000 - call_trace=d:\Desenvolvimento\PUC\rescue-api\.venv\Lib\site-packages\werkzeug\_internal.py L97  
[2025-04-10 20:25:14,816] INFO _log() L97   [33mPress CTRL+C to quit[0m - call_trace=d:\Desenvolvimento\PUC\rescue-api\.venv\Lib\site-packages\werkzeug\_internal.py L97  
[2025-04-10 20:25:14,818] INFO _log() L97    * Restarting with stat - call_trace=d:\Desenvolvimento\PUC\rescue-api\.venv\Lib\site-packages\werkzeug\_internal.py L97  
